Workbook

Sheet StockAnalysis_JSG_All_Enriched_
A1: Symbol | B1: Type | C1: Name | D1: Dividend Yield | E1: Growth Score | F1: Optionable | G1: Weekly Verdict | H1: Direction | I1: Confidence % | J1: SELL PUT Suitability | K1: SELL CALL Suitability | L1: Premium ROI
A2: WDC | B2: EQ | C2: Western Digital Corporation | D2: 0.0011 | E2: 83.7 | F2: Yes | G2: STRONG_BULLISH | H2: BULLISH | I2: 77.97 | J2: High | K2: Covered call only if already held | L2: 13.28% (SELL PUT, exp 20260821)
A3: AMAT | B3: EQ | C3: Applied Materials, Inc. | D3: 0.0042 | E3: 83.7 | F3: Yes | G3: STRONG_BULLISH | H3: BULLISH | I3: 83.51 | J3: High | K3: Covered call only if already held | L3: 10.79% (SELL PUT, exp 20260821)
A4: TER | B4: EQ | C4: Teradyne, Inc. | D4: 0.0014 | E4: 73.5 | F4: Yes | G4: STRONG_BULLISH | H4: BULLISH | I4: 76.03 | J4: High | K4: Covered call only if already held | L4: 13.01% (SELL PUT, exp 20260821)
A5: AMD | B5: EQ | C5: Advanced Micro Devices, Inc. | D5: - | E5: 92 | F5: Yes | G5: STRONG_BULLISH | H5: BULLISH | I5: 80.96 | J5: High | K5: Covered call only if already held | L5: 9.13% (SELL PUT, exp 20260821)
A6: COHR | B6: EQ | C6: Coherent Corp. | D6: - | E6: 99.7 | F6: Yes | G6: BULLISH | H6: MIXED | I6: 34.04 | J6: Medium | K6: Medium covered-call candidate | L6: 12.63% (SELL PUT, exp 20260821)
A7: HPE | B7: EQ | C7: Hewlett Packard Enterprise Company | D7: 0.0119 | E7: 82.4 | F7: Yes | G7: STRONG_BULLISH | H7: BULLISH | I7: 97.68 | J7: High | K7: Covered call only if already held | L7: 7.38% (SELL PUT, exp 20260821)
A8: VRT | B8: EQ | C8: Vertiv Holdings Co | D8: 0.001 | E8: 89.3 | F8: Yes | G8: STRONG_BULLISH | H8: BULLISH | I8: 73.11 | J8: High | K8: Covered call only if already held | L8: 8.18% (SELL PUT, exp 20260821)
A9: DELL | B9: EQ | C9: Dell Technologies Inc. | D9: 0.0062 | E9: 86 | F9: Yes | G9: STRONG_BULLISH | H9: BULLISH | I9: 55.12 | J9: High | K9: Covered call only if already held | L9: 8.95% (SELL PUT, exp 20260821)
A10: DDOG | B10: EQ | C10: Datadog, Inc. | D10: - | E10: 75.7 | F10: Yes | G10: BULLISH | H10: BULLISH | I10: 77.12 | J10: High | K10: Covered call only if already held | L10: 7.70% (SELL PUT, exp 20260821)
A11: INTC | B11: EQ | C11: Intel Corporation | D11: - | E11: 78.8 | F11: Yes | G11: STRONG_BULLISH | H11: MIXED | I11: 31.95 | J11: Medium | K11: Medium covered-call candidate | L11: 11.70% (SELL PUT, exp 20260821)
A12: LITE | B12: EQ | C12: Lumentum Holdings Inc. | D12: - | E12: 100 | F12: Yes | G12: STRONG_BULLISH | H12: BULLISH | I12: 94.25 | J12: Medium-High | K12: Covered call only if already held
A13: STT | B13: EQ | C13: State Street Corporation | D13: 0.02 | E13: 72.5 | F13: Yes | G13: STRONG_BULLISH | H13: BULLISH | I13: 100 | J13: Medium-High | K13: Covered call only if already held
A14: FTNT | B14: EQ | C14: Fortinet, Inc. | D14: - | E14: 74.7 | F14: Yes | G14: BULLISH | H14: BULLISH | I14: 63.35 | J14: High | K14: Covered call only if already held | L14: 7.72% (SELL PUT, exp 20260821)
A15: PSX | B15: EQ | C15: Phillips 66 | D15: 0.024 | E15: 66.6 | F15: Yes | G15: STRONG_BULLISH | H15: BULLISH | I15: 100 | J15: Medium-High | K15: Covered call only if already held
A16: CFG | B16: EQ | C16: Citizens Financial Group, Inc. | D16: 0.0257 | E16: 64 | F16: Yes | G16: STRONG_BULLISH | H16: BULLISH | I16: 97.65 | J16: Medium-High | K16: Covered call only if already held
A17: HST | B17: EQ | C17: Host Hotels & Resorts, Inc. | D17: 0.0378 | E17: 60.1 | F17: Yes | G17: STRONG_BULLISH | H17: BULLISH | I17: 100 | J17: Medium-High | K17: Covered call only if already held
A18: ANET | B18: EQ | C18: Arista Networks, Inc. | D18: - | E18: 82.8 | F18: Yes | G18: STRONG_BULLISH | H18: BULLISH | I18: 100 | J18: Medium-High | K18: Covered call only if already held
A19: VTRS | B19: EQ | C19: Viatris Inc. | D19: 0.0273 | E19: 57.9 | F19: Yes | G19: STRONG_BULLISH | H19: BULLISH | I19: 100 | J19: Medium-High | K19: Covered call only if already held
A20: CASY | B20: EQ | C20: Casey's General Stores, Inc. | D20: 0.003 | E20: 79.7 | F20: Yes | G20: STRONG_BULLISH | H20: BULLISH | I20: 100 | J20: Medium-High | K20: Covered call only if already held
A21: CAT | B21: EQ | C21: Caterpillar Inc. | D21: 0.008 | E21: 79.6 | F21: Yes | G21: STRONG_BULLISH | H21: BULLISH | I21: 99.9 | J21: Medium-High | K21: Covered call only if already held
A22: WAB | B22: EQ | C22: Westinghouse Air Brake Technologies Corporation | D22: 0.0043 | E22: 79 | F22: Yes | G22: STRONG_BULLISH | H22: BULLISH | I22: 100 | J22: Medium-High | K22: Covered call only if already held
A23: SPG | B23: EQ | C23: Simon Property Group, Inc. | D23: 0.0392 | E23: 55.3 | F23: Yes | G23: STRONG_BULLISH | H23: BULLISH | I23: 100 | J23: Medium-High | K23: Covered call only if already held
A24: HWM | B24: EQ | C24: Howmet Aerospace Inc. | D24: 0.002 | E24: 78 | F24: Yes | G24: STRONG_BULLISH | H24: BULLISH | I24: 100 | J24: Medium-High | K24: Covered call only if already held
A25: FITB | B25: EQ | C25: Fifth Third Bancorp | D25: 0.0283 | E25: 55 | F25: Yes | G25: STRONG_BULLISH | H25: BULLISH | I25: 100 | J25: Medium-High | K25: Covered call only if already held
A26: CVS | B26: EQ | C26: CVS Health Corporation | D26: 0.0255 | E26: 54.9 | F26: Yes | G26: STRONG_BULLISH | H26: BULLISH | I26: 100 | J26: Medium-High | K26: Covered call only if already held
A27: XOM | B27: EQ | C27: ExxonMobil Holdings Corporation | D27: 0.0265 | E27: 54.7 | F27: Yes | G27: STRONG_BULLISH | H27: BULLISH | I27: 100 | J27: Medium-High | K27: Covered call only if already held
A28: APA | B28: EQ | C28: APA Corporation | D28: 0.0268 | E28: 54.5 | F28: Yes | G28: STRONG_BULLISH | H28: BULLISH | I28: 100 | J28: Medium-High | K28: Covered call only if already held
A29: VTR | B29: EQ | C29: Ventas, Inc. | D29: 0.0222 | E29: 54.3 | F29: Yes | G29: STRONG_BULLISH | H29: BULLISH | I29: 100 | J29: Medium-High | K29: Covered call only if already held
A30: MPC | B30: EQ | C30: Marathon Petroleum Corporation | D30: 0.0126 | E30: 75.7 | F30: Yes | G30: STRONG_BULLISH | H30: BULLISH | I30: 100 | J30: Medium-High | K30: Covered call only if already held
... A34: ABBV | B34: EQ | C34: AbbVie Inc. | D34: 0.0276 | E34: 52.2 | F34: Yes | G34: STRONG_BULLISH | H34: BULLISH | I34: 100 | J34: Medium-High | K34: Covered call only if already held
A35: PANW | B35: EQ | C35: Palo Alto Networks, Inc. | D35: - | E35: 86.5 | F35: Yes | G35: STRONG_BULLISH | H35: BULLISH | I35: 83.91 | J35: Medium-High | K35: Covered call only if already held
A36: MRK | B36: EQ | C36: Merck & Co., Inc. | D36: 0.0261 | E36: 51.6 | F36: Yes | G36: STRONG_BULLISH | H36: BULLISH | I36: 100 | J36: Medium-High | K36: Covered call only if already held
A37: GS | B37: EQ | C37: The Goldman Sachs Group, Inc. | D37: 0.0196 | E37: 74.3 | F37: Yes | G37: STRONG_BULLISH | H37: BULLISH | I37: 100 | J37: Medium-High | K37: Covered call only if already held
A38: MTB | B38: EQ | C38: M&T Bank Corporation | D38: 0.0244 | E38: 51.2 | F38: Yes | G38: STRONG_BULLISH | H38: BULLISH | I38: 100 | J38: Medium-High | K38: Covered call only if already held
A39: PM | B39: EQ | C39: Philip Morris International Inc. | D39: 0.0308 | E39: 50.9 | F39: Yes | G39: STRONG_BULLISH | H39: BULLISH | I39: 100 | J39: Medium-High | K39: Covered call only if already held
A40: UAL | B40: EQ | C40: United Airlines Holdings, Inc. | D40: - | E40: 73.4 | F40: Yes | G40: STRONG_BULLISH | H40: BULLISH | I40: 100 | J40: Medium-High | K40: Covered call only if already held
A41: APH | B41: EQ | C41: Amphenol Corporation | D41: 0.0062 | E41: 83.6 | F41: Yes | G41: STRONG_BULLISH | H41: BULLISH | I41: 85.3 | J41: Medium-High | K41: Covered call only if already held
A42: JNJ | B42: EQ | C42: Johnson & Johnson | D42: 0.0209 | E42: 50.2 | F42: Yes | G42: STRONG_BULLISH | H42: BULLISH | I42: 100 | J42: Medium-High | K42: Covered call only if already held
A43: FANG | B43: EQ | C43: Diamondback Energy, Inc. | D43: 0.0217 | E43: 49.9 | F43: Yes | G43: STRONG_BULLISH | H43: BULLISH | I43: 100 | J43: Medium-High | K43: Covered call only if already held
...

Sheet newlist
A1: AssetClass | B1: Symbol | C1: InOld
A2: EQ | B2: A | C2: =IF(ISERROR(_xlfn.XMATCH(B2,oldlist!B:B,0)),"not found","found") -> found
A3: EQ | B3: AAPL | C3: =IF(ISERROR(_xlfn.XMATCH(B3,oldlist!B:B,0)),"not found","found") -> found
A4: EQ | B4: ABBV | C4: =IF(ISERROR(_xlfn.XMATCH(B4,oldlist!B:B,0)),"not found","found") -> found
A5: EQ | B5: ABNB | C5: =IF(ISERROR(_xlfn.XMATCH(B5,oldlist!B:B,0)),"not found","found") -> found
A6: EQ | B6: ABT | C6: =IF(ISERROR(_xlfn.XMATCH(B6,oldlist!B:B,0)),"not found","found") -> found
A7: EQ | B7: ACGL | C7: =IF(ISERROR(_xlfn.XMATCH(B7,oldlist!B:B,0)),"not found","found") -> found
A8: EQ | B8: ACN | C8: =IF(ISERROR(_xlfn.XMATCH(B8,oldlist!B:B,0)),"not found","found") -> found
A9: EQ | B9: ADBE | C9: =IF(ISERROR(_xlfn.XMATCH(B9,oldlist!B:B,0)),"not found","found") -> found
A10: EQ | B10: ADI | C10: =IF(ISERROR(_xlfn.XMATCH(B10,oldlist!B:B,0)),"not found","found") -> found
A11: EQ | B11: ADM | C11: =IF(ISERROR(_xlfn.XMATCH(B11,oldlist!B:B,0)),"not found","found") -> found
A12: EQ | B12: ADP | C12: =IF(ISERROR(_xlfn.XMATCH(B12,oldlist!B:B,0)),"not found","found") -> found
A13: EQ | B13: ADSK | C13: =IF(ISERROR(_xlfn.XMATCH(B13,oldlist!B:B,0)),"not found","found") -> found
... A1370: ETF | B1370: YLDE | C1370: =IF(ISERROR(_xlfn.XMATCH(B1370,oldlist!B:B,0)),"not found","found") -> not found

Sheet oldlist
A1: AssetClass | B1: Symbol | C1: InNew
A2: EQ | B2: A | C2: =IF(ISERROR(_xlfn.XMATCH(B2,newlist!B:B,0)),"not found","found") -> found
A3: EQ | B3: AAPL | C3: =IF(ISERROR(_xlfn.XMATCH(B3,newlist!B:B,0)),"not found","found") -> found
A4: EQ | B4: ABBV | C4: =IF(ISERROR(_xlfn.XMATCH(B4,newlist!B:B,0)),"not found","found") -> found
A5: EQ | B5: ABNB | C5: =IF(ISERROR(_xlfn.XMATCH(B5,newlist!B:B,0)),"not found","found") -> found
A6: EQ | B6: ABT | C6: =IF(ISERROR(_xlfn.XMATCH(B6,newlist!B:B,0)),"not found","found") -> found
A7: EQ | B7: ACGL | C7: =IF(ISERROR(_xlfn.XMATCH(B7,newlist!B:B,0)),"not found","found") -> found
A8: EQ | B8: ADBE | C8: =IF(ISERROR(_xlfn.XMATCH(B8,newlist!B:B,0)),"not found","found") -> found
A9: EQ | B9: ADI | C9: =IF(ISERROR(_xlfn.XMATCH(B9,newlist!B:B,0)),"not found","found") -> found
A10: EQ | B10: ADM | C10: =IF(ISERROR(_xlfn.XMATCH(B10,newlist!B:B,0)),"not found","found") -> found
A11: EQ | B11: ADP | C11: =IF(ISERROR(_xlfn.XMATCH(B11,newlist!B:B,0)),"not found","found") -> found
A12: EQ | B12: AEE | C12: =IF(ISERROR(_xlfn.XMATCH(B12,newlist!B:B,0)),"not found","found") -> found
A13: EQ | B13: AEP | C13: =IF(ISERROR(_xlfn.XMATCH(B13,newlist!B:B,0)),"not found","found") -> found
... A1213: ETF | B1213: XOEF | C1213: =IF(ISERROR(_xlfn.XMATCH(B1213,newlist!B:B,0)),"not found","found") -> found

Sheet summary
A1: InOld | D1: InNew
A2: found | B2: =COUNTIF(newlist!C:C,A2) -> 1183 | D2: found | E2: =COUNTIF(oldlist!C:C,A2) -> 1183
A3: not found | B3: =COUNTIF(newlist!C:C,A3) -> 186 | D3: not found | E3: =COUNTIF(oldlist!C:C,A3) -> 29
